<!doctype html>
<html lang="tr">

<head>
    <meta charset="utf-8">
    <meta name="viewport" content="width=device-width, initial-scale=1">
    <title>Hata yönetimi</title>
    <link href="https://cdn.jsdelivr.net/npm/bootstrap@5.2.0/dist/css/bootstrap.min.css" rel="stylesheet"
        integrity="sha384-gH2yIJqKdNHPEq0n4Mqa/HGKIhSkIHeL5AyhkYV8i59U5AR6csBvApHHNl/vI1Bx" crossorigin="anonymous">
</head>

<body>
    <div class="container mt-5">
        <div class="row">
            <div class="col-sm-8 offset-sm-2">
                <h1>Try Ve Catch Kullanımı</h1>
                <p><strong>try...catch</strong> ifadesini basitçe ifade edersek; Herhangi bir iş yaparken bir hatayla
                    karşılaşılma durumunun ele alınması anlamına gelmektedir. </p>
                <p><strong>try</strong> anahtar kelimesi kodları çalışma zamanında test etmek için kullanılırken,
                    <strong>catch</strong> anahtar kelimesi ise çalışma zamanında hata çıkması durumunda bu hataları
                    yakalamak için kullanılır.
                </p>
                <p>Basit bir try catch bloğu şu şekildedir.</p>
                <p>try {
                    <br>//Çalıştırılacak kodlar
                    <br>}catch(hata) {
                    <br>//Hata yakalandığında çalışacak kodlar
                    <br>}finally {
                    <br>//try tamamlandıktan sonra hata olsada olmasada çalışacak olan kodlar.
                    <br>}
                </p>
                <p>catch bloğunda yazılmış olan <strong>hata</strong> değişkeni oluşacak istisnayı taşıyacak olan
                    değişken adıdır. Buraya herhangi bir isim verilebilir fakat yaygın olarak
                    <strong>exception</strong>ın ilk harfi olan <strong>e,err</strong> gibi ifadelerle isimlendirilir.
                    Bizde örneklerimizde bu yaygın isimlendirmelerden <strong>err</strong>yi kullanacağız.
                </p>
                <p>Basit bir örnekle daha iyi anlamaya çalışalım.</p>
                <p>try {
                    <br>hello();
                    <br>}catch (err) {
                    <br>console.error(err);
                    <br>// beklenen çıktı: ReferenceError: hello is not defined
                    <br>// hata mesajları tarayıcıya göre değişiklik gösterecektir
                    <br>}
                </p>
                <p>Örnekteki kod bloğunda <strong>hello()</strong> diye bir fonksiyon çalıştırılmak isteniyor ama böyle
                    bir fonksiyon olmadığı için catch bloğu içerisine düşüyor ve catch bloğuna düştükten sonra
                    <strong>console.error()</strong> fonksiyonu ile konsolda hata gösteriliyor.
                </p>
                <h3>Throw İle İstisnalar Oluşturma</h3>
                <p>Normalde kod çalışırken bir hata oluştuğunda, JavaScript dur ve bir hata mesajı oluşturur. Bu duruma
                    JavaScript bir istisnae atar (bir hata atar) olarak adlandırılır.</p>
                <p><strong>JavaScript aslında iki özelliğe sahip bir Error nesnesi oluşturacaktır: isim ve
                        mesaj.</strong></p>
                <p><strong>throw</strong> ifadesi bize özel hatalarımızı oluşturmanıza olanak tanır. Teknik olarak
                    <strong>throw</strong> ifadesi bize özel hatalarımızı oluşturmamıza olanak tanır. Teknik olarak
                    <strong>throw</strong> ile bir istisna (hata) atılabilir.
                </p>
                <p>throw "Çok büyük"; // Çok büyük hatası at, oluştur
                    <br>throw 500; // 500 numarası hatasını at, oluştur
                </p>
                <p>Sonuç olarak <strong>throw</strong> ile birlikte <strong>try...catch</strong> ifadesini kullanırsak,
                    program akışını kontrol edebilir ve özel hata mesajları oluşturabiliriz.</p>
                <p>Basit bir örnekle daha iyi anlamaya çalışalım.</p>
                <p><input type="text" id="dogumTarihi" />
                    <br><button class="btn btn-success" onclick="valid()">Gönder</button>
                </p>
                <p>Yukarıdaki gibi "doğumTarihi" adında bir input nesnesi oluşturalım ve butona tıkladığımızda eğer
                    "doğumTarihi" adındaki input nesnemize bir şey girilmediyse throw ifadesiyle kolay bir şekilde
                    exception oluşturabiliriz.</p>
                <p>function valid(){
                    <br>try {
                    <br>if (document.querySelector("#dogumTarihi").value == "") {
                    <br>throw 'Doğum tarihini boş geçemezsiniz';
                    <br>};
                    <br>}catch(err) {
                    <br>alert(err);
                    <br>}
                    <br>}
                </p>
            </div>
        </div>
    </div>
    <script src="https://cdn.jsdelivr.net/npm/bootstrap@5.2.0/dist/js/bootstrap.bundle.min.js"
        integrity="sha384-A3rJD856KowSb7dwlZdYEkO39Gagi7vIsF0jrRAoQmDKKtQBHUuLZ9AsSv4jD4Xa"
        crossorigin="anonymous"></script>
    <script>
        function valid() {
            try {
                if (document.querySelector("#dogumTarihi").value == "") {
                    throw 'Doğum tarihini boş geçemezsiniz';
                };
            } catch (err) {
                alert(err);
            }
        }
    </script>
</body>

</html>